<?xml version="1.0" encoding="utf-8"?>
<!-- This URDF was automatically created by SolidWorks to URDF Exporter! Originally created by Stephen Brawner (brawner@gmail.com) 
     Commit Version: 1.5.1-0-g916b5db  Build Version: 1.5.7152.31018
     For more information, please see http://wiki.ros.org/sw_urdf_exporter -->
<robot
  name="leg_robotv4">
  <link
    name="base_link">
    <inertial>
      <origin
        xyz="-0.0014321 -0.00041851 -0.040306"
        rpy="0 0 0" />
      <mass
        value="2.4018" />
      <inertia
        ixx="0.009591"
        ixy="-1.9337E-07"
        ixz="1.2072E-07"
        iyy="0.0070769"
        iyz="-2.7325E-07"
        izz="0.015485" />
    </inertial>
    <visual>
      <origin
        xyz="0 0 0"
        rpy="0 0 0" />
      <geometry>
        <mesh
          filename="package://leg_robotv4/meshes/base_link.STL" />
      </geometry>
      <material
        name="">
        <color
          rgba="0.79216 0.81961 0.93333 1" />
      </material>
    </visual>
    <collision>
      <origin
        xyz="0 0 0"
        rpy="0 0 0" />
      <geometry>
        <mesh
          filename="package://leg_robotv4/meshes/base_link.STL" />
      </geometry>
    </collision>
  </link>
  <link
    name="left_link1">
    <inertial>
      <origin
        xyz="-1.1057E-06 0.21548 -0.046266"
        rpy="0 0 0" />
      <mass
        value="0.43137" />
      <inertia
        ixx="0.0027266"
        ixy="9.8E-06"
        ixz="-5.4625E-08"
        iyy="0.00020436"
        iyz="1.5473E-07"
        izz="0.0026126" />
    </inertial>
    <visual>
      <origin
        xyz="0 0 0"
        rpy="0 0 0" />
      <geometry>
        <mesh
          filename="package://leg_robotv4/meshes/left_link1.STL" />
      </geometry>
      <material
        name="">
        <color
          rgba="0.79216 0.81961 0.93333 1" />
      </material>
    </visual>
    <collision>
      <origin
        xyz="0 0 0"
        rpy="0 0 0" />
      <geometry>
        <mesh
          filename="package://leg_robotv4/meshes/left_link1.STL" />
      </geometry>
    </collision>
  </link>
  <joint
    name="left_joint1"
    type="revolute">
    <origin
      xyz="-0.0405 0.12365 0.06"
      rpy="1.5708 0 0" />
    <parent
      link="base_link" />
    <child
      link="left_link1" />
    <axis
      xyz="0 0 1" />
    <limit
      lower="-1.571"
      upper="1.571"
      effort="100"
      velocity="3" />
  </joint>
  <link
    name="left_link2">
    <inertial>
      <origin
        xyz="0.17796 0.0015786 -0.047904"
        rpy="0 0 0" />
      <mass
        value="0.45541" />
      <inertia
        ixx="0.00023283"
        ixy="4.9149E-06"
        ixz="3.255E-18"
        iyy="0.0027437"
        iyz="1.3949E-17"
        izz="0.002625" />
    </inertial>
    <visual>
      <origin
        xyz="0 0 0"
        rpy="0 0 0" />
      <geometry>
        <mesh
          filename="package://leg_robotv4/meshes/left_link2.STL" />
      </geometry>
      <material
        name="">
        <color
          rgba="0.79216 0.81961 0.93333 1" />
      </material>
    </visual>
    <collision>
      <origin
        xyz="0 0 0"
        rpy="0 0 0" />
      <geometry>
        <mesh
          filename="package://leg_robotv4/meshes/left_link2.STL" />
      </geometry>
    </collision>
  </link>
  <joint
    name="left_joint2"
    type="revolute">
    <origin
      xyz="0 0.438 0"
      rpy="0 0 1.5708" />
    <parent
      link="left_link1" />
    <child
      link="left_link2" />
    <axis
      xyz="0 0 1" />
    <limit
      lower="-1.571"
      upper="1.571"
      effort="150"
      velocity="3" />
  </joint>
  <link
    name="left_link3">
    <inertial>
      <origin
        xyz="0.0366754335013657 -0.049330963427318 -0.0458015482204589"
        rpy="0 0 0" />
      <mass
        value="0.291189773826857" />
      <inertia
        ixx="0.000684347300419343"
        ixy="-6.03575796715871E-08"
        ixz="-1.36625094874573E-07"
        iyy="0.000116061793166679"
        iyz="9.66829388753254E-08"
        izz="0.000610485905391525" />
    </inertial>
    <visual>
      <origin
        xyz="0 0 0"
        rpy="0 0 0" />
      <geometry>
        <mesh
          filename="package://leg_robotv4/meshes/left_link3.STL" />
      </geometry>
      <material
        name="">
        <color
          rgba="0.792156862745098 0.819607843137255 0.933333333333333 1" />
      </material>
    </visual>
    <collision>
      <origin
        xyz="0 0 0"
        rpy="0 0 0" />
      <geometry>
        <mesh
          filename="package://leg_robotv4/meshes/left_link3.STL" />
      </geometry>
    </collision>
  </link>
  <joint
    name="left_joint3"
    type="revolute">
    <origin
      xyz="0.44 0 0"
      rpy="0 0 0" />
    <parent
      link="left_link2" />
    <child
      link="left_link3" />
    <axis
      xyz="0 0 1" />
    <limit
      lower="0"
      upper="1.571"
      effort="200"
      velocity="3" />
  </joint>
  <link
    name="right_link1">
    <inertial>
      <origin
        xyz="0 0 0"
        rpy="0 0 0" />
      <mass
        value="0" />
      <inertia
        ixx="0"
        ixy="0"
        ixz="0"
        iyy="0"
        iyz="0"
        izz="0" />
    </inertial>
    <visual>
      <origin
        xyz="0 0 0"
        rpy="0 0 0" />
      <geometry>
        <mesh
          filename="package://leg_robotv4/meshes/right_link1.STL" />
      </geometry>
      <material
        name="">
        <color
          rgba="1 1 1 1" />
      </material>
    </visual>
    <collision>
      <origin
        xyz="0 0 0"
        rpy="0 0 0" />
      <geometry>
        <mesh
          filename="package://leg_robotv4/meshes/right_link1.STL" />
      </geometry>
    </collision>
  </link>
  <joint
    name="right_joint1"
    type="revolute">
    <origin
      xyz="-0.0405 -0.114 0.06"
      rpy="1.5708 0 0" />
    <parent
      link="base_link" />
    <child
      link="right_link1" />
    <axis
      xyz="0 0 1" />
    <limit
      lower="-1.571"
      upper="1.571"
      effort="100"
      velocity="3" />
  </joint>
  <link
    name="right_link2">
    <inertial>
      <origin
        xyz="0.177961893333791 0.00157862107612522 0.0544457699691984"
        rpy="0 0 0" />
      <mass
        value="0.455413997264767" />
      <inertia
        ixx="0.000232825591707953"
        ixy="4.91487669826869E-06"
        ixz="3.72790344262255E-18"
        iyy="0.00274374190170979"
        iyz="1.40593641604864E-17"
        izz="0.00262496586389582" />
    </inertial>
    <visual>
      <origin
        xyz="0 0 0"
        rpy="0 0 0" />
      <geometry>
        <mesh
          filename="package://leg_robotv4/meshes/right_link2.STL" />
      </geometry>
      <material
        name="">
        <color
          rgba="0.792156862745098 0.819607843137255 0.933333333333333 1" />
      </material>
    </visual>
    <collision>
      <origin
        xyz="0 0 0"
        rpy="0 0 0" />
      <geometry>
        <mesh
          filename="package://leg_robotv4/meshes/right_link2.STL" />
      </geometry>
    </collision>
  </link>
  <joint
    name="right_joint2"
    type="revolute">
    <origin
      xyz="0 0.438 0"
      rpy="0 0 1.5708" />
    <parent
      link="right_link1" />
    <child
      link="right_link2" />
    <axis
      xyz="0 0 1" />
    <limit
      lower="-1.571"
      upper="1.571"
      effort="150"
      velocity="3" />
  </joint>
  <link
    name="right_link3">
    <inertial>
      <origin
        xyz="0.0366754335013658 -0.0493309634273079 0.0491984517795272"
        rpy="0 0 0" />
      <mass
        value="0.291189773826858" />
      <inertia
        ixx="0.000684347300419343"
        ixy="-6.03575796718335E-08"
        ixz="-1.36625094874698E-07"
        iyy="0.000116061793166679"
        iyz="9.6682938767452E-08"
        izz="0.000610485905391525" />
    </inertial>
    <visual>
      <origin
        xyz="0 0 0"
        rpy="0 0 0" />
      <geometry>
        <mesh
          filename="package://leg_robotv4/meshes/right_link3.STL" />
      </geometry>
      <material
        name="">
        <color
          rgba="0.792156862745098 0.819607843137255 0.933333333333333 1" />
      </material>
    </visual>
    <collision>
      <origin
        xyz="0 0 0"
        rpy="0 0 0" />
      <geometry>
        <mesh
          filename="package://leg_robotv4/meshes/right_link3.STL" />
      </geometry>
    </collision>
  </link>
  <joint
    name="right_joint3"
    type="revolute">
    <origin
      xyz="0.44 0 0.00735"
      rpy="0 0 0" />
    <parent
      link="right_link2" />
    <child
      link="right_link3" />
    <axis
      xyz="0 0 1" />
    <limit
      lower="0"
      upper="1.571"
      effort="200"
      velocity="3" />
  </joint>
</robot>